<?xml version="1.0" ?>
<!-- =================================================================================== -->
<!-- |    This document was autogenerated by xacro from arm.xacro                      | -->
<!-- |    EDITING THIS FILE BY HAND IS NOT RECOMMENDED                                 | -->
<!-- =================================================================================== -->
<robot name="vison_arm">
  <!-- mass is in kg
         lenths/positions in m
         inertia in kgm2
         velocity - revoluts = rad/s 
                  - prismatic(sliding) = m/s
         effort   - revoluts = Nm(torqe) 
                  - prismatic(sliding) = N -->
  <link name="base_link">
    <visual>
      <geometry>
        <box size="0.1 0.1 0.1"/>
      </geometry>
      <material name="grey">
        <color rgba="0.5 0.5 0.5 1.0"/>
      </material>
    </visual>
    <collision>
      <geometry>
        <box size="0.1 0.1 0.1"/>
      </geometry>
    </collision>
    <inertial>
      <mass value="0,5"/>
      <inertia ixx="0.001" ixy="0" ixz="0" iyy="0.001" iyz="0" izz="0.001"/>
    </inertial>
  </link>
  <joint name="world_to_base_joint" type="fixed">
    <parent link="world"/>
    <child link="base_link"/>
    <origin rpy="0 0 0" xyz="0 0 1"/>
  </joint>
  <!-- Define an empty 'world' link so it can serve as the parent (root) for the first joint.
     This satisfies the URDF rule that every joint must connect a parent and child link.
     In this case, 'world' is the static environment (ground), and 'base_link' is the robot's first link. -->
  <link name="world"/>
  <link name="upper_arm_link">
    <visual>
      <geometry>
        <box size="0.08 0.08 0.5"/>
      </geometry>
      <origin rpy="0 0 0" xyz="0 0 -0.25"/>
      <material name="blue">
        <color rgba="0.0 0.0 0.8 1.0"/>
      </material>
    </visual>
    <collision>
      <geometry>
        <box size="0.08 0.08 0.5"/>
      </geometry>
      <origin rpy="0 0 0" xyz="0 0 -0.25"/>
    </collision>
    <inertial>
      <mass value="1.0"/>
      <origin rpy="0 0 0" xyz="0 0 -0.25"/>
      <inertia ixx="0.005" ixy="0.0" ixz="0.0" iyy="0.005" iyz="0.0" izz="0.001"/>
    </inertial>
  </link>
  <joint name="base_to_upper_arm_joint" type="fixed">
    <parent link="base_link"/>
    <child link="upper_arm_link"/>
    <origin rpy="0 0 0" xyz="0 0 0"/>
  </joint>
  <link name="lower_arm_link">
    <visual>
      <geometry>
        <box size="0.08 0.08 0.5"/>
      </geometry>
      <origin rpy="0 0 0" xyz="0 0 -0.25"/>
      <material name="red">
        <color rgba="0.8 0.0 0.0 1.0"/>
      </material>
    </visual>
    <collision>
      <geometry>
        <box size="0.08 0.08 0.5"/>
      </geometry>
      <origin rpy="0 0 0" xyz="0 0 -0.25"/>
    </collision>
    <inertial>
      <mass value="1.0"/>
      <origin rpy="0 0 0" xyz="0 0 -0.25"/>
      <inertia ixx="0.005" ixy="0.0" ixz="0.0" iyy="0.005" iyz="0.0" izz="0.001"/>
    </inertial>
  </link>
  <joint name="elbow_joint" type="revolute">
    <parent link="upper_arm_link"/>
    <child link="lower_arm_link"/>
    <!--lower and upper limits are in radiens-->
    <origin rpy="0 0 0" xyz="0 0 -0.5"/>
    <axis xyz="0 1 0"/>
    <limit effort="100.0" lower="0.1" upper="2.721" velocity="1.0"/>
  </joint>
</robot>
